Workbook

Sheet nba_contracts_performance_final
A1: player | B1: team | C1: conference | D1: position_group | E1: age | F1: games_played | G1: minutes_per_game | H1: rebounds_per_game | I1: assists_per_game | J1: points_per_game | K1: salary_filled | L1: born
A2: Luka Dončić | B2: LAL | C2: West | D2: Guard | E2: 26 | F2: 64 | G2: 35.8 | H2: 7.7 | I2: 8.3 | J2: 33.5 | K2: 45999660 | L2: INT
A3: Shai Gilgeous-Alexander | B3: OKC | C3: West | D3: Guard | E3: 27 | F3: 68 | G3: 33.2 | H3: 4.3 | I3: 6.6 | J3: 31.1 | K3: 38333050 | L3: INT
A4: Anthony Edwards | B4: MIN | C4: West | D4: Guard | E4: 24 | F4: 61 | G4: 35 | H4: 5 | I4: 3.7 | J4: 28.8 | K4: 45550512 | L4: US
A5: Jaylen Brown | B5: BOS | C5: East | D5: Forward | E5: 29 | F5: 71 | G5: 34.4 | H5: 6.9 | I5: 5.1 | J5: 28.7 | K5: 53142264 | L5: US
A6: Tyrese Maxey | B6: PHI | C6: East | D6: Guard | E6: 25 | F6: 70 | G6: 38 | H6: 4.1 | I6: 6.6 | J6: 28.3 | K6: 37958760 | L6: US
A7: Kawhi Leonard | B7: LAC | C7: West | D7: Forward | E7: 34 | F7: 65 | G7: 32.1 | H7: 6.4 | I7: 3.6 | J7: 27.9 | K7: 50000000 | L7: US
A8: Donovan Mitchell | B8: CLE | C8: East | D8: Guard | E8: 29 | F8: 70 | G8: 33.5 | H8: 4.5 | I8: 5.7 | J8: 27.9 | K8: 46394100 | L8: US
A9: Nikola Jokić | B9: DEN | C9: West | D9: Center | E9: 30 | F9: 65 | G9: 34.8 | H9: 12.9 | I9: 10.7 | J9: 27.7 | K9: 55224526 | L9: INT
A10: Giannis Antetokounmpo | B10: MIL | C10: East | D10: Forward | E10: 31 | F10: 36 | G10: 28.9 | H10: 9.8 | I10: 5.4 | J10: 27.6 | K10: 54126450 | L10: INT
A11: Joel Embiid | B11: PHI | C11: East | D11: Center | E11: 31 | F11: 38 | G11: 31.6 | H11: 7.7 | I11: 3.9 | J11: 26.9 | K11: 55224526 | L11: INT
A12: Lauri Markkanen | B12: UTA | C12: West | D12: Forward | E12: 28 | F12: 42 | G12: 34.4 | H12: 6.9 | I12: 2.1 | J12: 26.7 | K12: 46394100 | L12: INT
A13: Stephen Curry | B13: GSW | C13: West | D13: Guard | E13: 37 | F13: 43 | G13: 30.9 | H13: 3.6 | I13: 4.7 | J13: 26.6 | K13: 59606817 | L13: US
... A567: Chucky Hepburn | B567: TOR | C567: East | D567: Guard | E567: 22 | F567: 2 | G567: 6.5 | H567: 0.5 | I567: 1 | J567: 0 | K567: 85300 | L567: US

Sheet Distribution Analysis
J3: Age Summary Statistics
J4: Mean : | K4: =AVERAGE(nba_contracts_performance_final!E2:E567) -> 25.931095
J5: Median : | K5: =MEDIAN(nba_contracts_performance_final!E2:E567) -> 25
J6: Std Dev : | K6: =_xlfn.STDEV.P(nba_contracts_performance_final!E2:E567) -> 4.2364548
J7: Skewness : | K7: =SKEW(nba_contracts_performance_final!E2:E567) -> 0.92842567
J8: Kurtosis : | K8: =KURT(nba_contracts_performance_final!E2:E567) -> 0.78619554
J10: The age distribution is right-skewed, with a slightly higher peak than a normal distribution, so it does not meet normality assumptions. This makes sense given the context, there are substantially fewer older players in the NBA, creating a longer tail toward higher ages rather than a symmetric spread.
J25: Games Played Summary Statistics
J26: Mean : | K26: =AVERAGE(nba_contracts_performance_final!F2:F567) -> 46.392226
J27: Median : | K27: =MEDIAN(nba_contracts_performance_final!F2:F567) -> 53
J28: Std Dev : | K28: =_xlfn.STDEV.P(nba_contracts_performance_final!F2:F567) -> 24.837882
J29: Skewness : | K29: =SKEW(nba_contracts_performance_final!F2:F567) -> -0.40936686
J30: Kurtosis : | K30: =KURT(nba_contracts_performance_final!F2:F567) -> -1.1602365
J33: The games played distribution is left-skewed, with a flatter peak than a normal distribution, so it does not meet normality assumptions. This makes sense given the context , it's more common for players to play the majority of games (barring injury), pushing most values toward the higher end and creating a longer tail toward fewer games played.
J44: Minutes/Game Summary Statistics
J45: Mean : | K45: =AVERAGE(nba_contracts_performance_final!G2:G567) -> 19.839929
J46: Median : | K46: =MEDIAN(nba_contracts_performance_final!G2:G567) -> 20.4
J47: Std Dev : | K47: =_xlfn.STDEV.P(nba_contracts_performance_final!G2:G567) -> 8.9317196
J48: Skewness : | K48: =SKEW(nba_contracts_performance_final!G2:G567) -> -0.097438714
J49: Kurtosis : | K49: =KURT(nba_contracts_performance_final!G2:G567) -> -1.046794
J51: Minutes per game is approximately symmetric , but flatter than normal, so it still does not fully meet normality assumptions. This makes sense given the context, since coaches often distribute minutes fairly evenly across a rotation rather than concentrating heavy minutes on just a few players except for the stars.
J64: Rebounds/Game Summary Statistics
J65: Mean : | K65: =AVERAGE(nba_contracts_performance_final!H2:H567) -> 3.6174912
J66: Median : | K66: =MEDIAN(nba_contracts_performance_final!H2:H567) -> 3.15
J67: Std Dev : | K67: =_xlfn.STDEV.P(nba_contracts_performance_final!H2:H567) -> 2.3583087
J68: Skewness : | K68: =SKEW(nba_contracts_performance_final!H2:H567) -> 1.1395506
J69: Kurtosis : | K69: =KURT(nba_contracts_performance_final!H2:H567) -> 1.3896846
J71: Rebounds per game is right-skewed with a peak higher than normal, so it does not meet normality assumptions. This makes sense given the context, since most players average a modest number of rebounds while a smaller group of taller, rebound-focused players pulls the distribution's tail toward higher values.
J87: Assists/Game Summary Statistics
J88: Mean : | K88: =AVERAGE(nba_contracts_performance_final!I2:I567) -> 2.1628975
J89: Median : | K89: =MEDIAN(nba_contracts_performance_final!I2:I567) -> 1.6
J90: Std Dev : | K90: =_xlfn.STDEV.P(nba_contracts_performance_final!I2:I567) -> 1.7968961
J91: Skewness : | K91: =SKEW(nba_contracts_performance_final!I2:I567) -> 1.5161336
J92: Kurtosis : | K92: =KURT(nba_contracts_performance_final!I2:I567) -> 2.4672944
J94: Assists per game is right-skewed with a peak higher than normal, so it does not meet normality assumptions. This makes sense given the context, since most players record relatively few assists while a smaller group of primary ball-handlers and playmakers drives the tail toward much higher values.
J109: Points/Game Summary Statistics
J110: Mean : | K110: =AVERAGE(nba_contracts_performance_final!J2:J567) -> 9.2731449
J111: Median : | K111: =MEDIAN(nba_contracts_performance_final!J2:J567) -> 8
J112: Std Dev : | K112: =_xlfn.STDEV.P(nba_contracts_performance_final!J2:J567) -> 6.4070263
J113: Skewness : | K113: =SKEW(nba_contracts_performance_final!J2:J567) -> 0.99187028
...

Sheet Probability Scenarios
A1: Variable Used: Salary_Filled
A4: Empirical Method used for all questions
A5: Question 1:
A6: What is the probability a player earns more than $10,000,000?
A8: Pr(X > 10,000,000) = | B8: =COUNTIF(nba_contracts_performance_final!K2:K567,">10000000")/COUNT(nba_contracts_performance_final!K2:K567) -> 0.2844523
A10: The probability tells us that the majority of players in our dataset earns less than $10,000,000 revealing that a relatively smaller portion (28%) of players represent the higher earning values. This shows along with the salary histogram, that salary is heavily right-skewed
A13: Question 2:
A14: What is the probability that a players salary falls between $1,000,000 and $5,000,000?
A16: Pr(X <= 5,000,000) = | B16: =COUNTIF(nba_contracts_performance_final!K2:K567,"<=5000000")/COUNT(nba_contracts_performance_final!K2:K567) -> 0.57243816
A17: Pr(X <= 1,000,000) = | B17: =COUNTIF(nba_contracts_performance_final!K2:K567,"<=1000000")/COUNT(nba_contracts_performance_final!K2:K567) -> 0.25088339
A18: Pr(1,000,000 < = X <= 5,000,000) = | C18: =B16-B17 -> 0.32155477
A20: This shows that roughly a third of players fall into the mid-level salary range while a decent share earn at or below $1,000,000 (likely rookies or players on minimum contracts).
A23: Question 3:
A24: What salary earnings amount marks the 90th percentile?
A26: 90th percentile Salary: | B26: =PERCENTILE(nba_contracts_performance_final!K2:K567,0.9) -> 28361608
A28: This shows that a player needs to earn roughly $28,360,000 or more to be in the top 10% of the salary distribution, showing just how far the highest paid players' salaries pull away from the rest of the league.

Sheet Probability Commentary
A1: Probability Commentary
A3: None of the seven continuous variables in this dataset met the assumptions of a normal distribution. Age, rebounds/game, assists/game, points/game, and especially salary were all right-skewed with sharp peaks, while games played was left-skewed and minutes/game, though almost symmetric, was flatter than a normal curve. Salary was the most skewed distribution, which logically makes sense because most players make salaries on the lower - middle end of the range, but the superstar players with extremely high contracts skew the distribution and increase the average.
A4: Since salary was skewed we used percentiles from the dataset instead of the normal distribution to calculate probabilities. This was interesting to analyze from the perspective of a team manager and seeing the math behind contracts and salaries. Only about 28% of players earn over $10 million helps to show what a "top-tier" contract would look like, and about a third of players fall between $1–5 million gives a realistic range for typical deals. The 90th percentile (about $28.36 million) also gives a clear cutoff for spotting superstar-level salaries. The biggest surprise was how different the average salary (~$9.3 million) was from the median (~$3.6 million) emphasizing that the few very high-paid stars can pull the "average" way up, making it a poor way to describe a typical player's pay.

Sheet AI Usage
A1: Usage of AI
A2: Claude was used in the probability tab to get different ideas for different types of questions pertaining to our dataset.
A3: Prompt:
A4: can you give me a question that would allow to use the percentile function
A6: Output:
A7: Here's one that fits naturally with the PERCENTILE function:
A8: What salary value marks the 90th percentile — meaning, what salary would a player need to earn to be in the top 10% of earners in the dataset?
A9: You'd calculate this with:
A10: "=PERCENTILE(nba_contracts_performance_final!K2:K567,0.9)"
A12: The limitation I faced was finding different ways to pose questions to uncover the true distribution of the salary earnings from players in our dataset. I overcame this by finding different ways to use functions discussed in class to reveal a better story from the salary column.

Sheet project_requirements
A1: Q1 | B1: ✓
A2: Q2 | B2: ✓
A3: Q3 | B3: Player's salary will be out main continuous variable of interest
B4: We want to explore it against performance metrics.
B5: It can still be very interesting in binary form, using it to look at over or under certain threshold values.
A6: Q4
A7: Contract data | B7: spotrac.com/nba/rankings/player/_/year/2025/sort/cap_base
A8: Performance data | B8: basketball-reference.com/leagues/NBA_2026_per_game.html
A9: Int. status | B9: pr.nba.com/international-players-2025-26-nba-rosters
A10: Accessed | B10: Navigating through these public data sets and compiling them into one full data set
A12: Q5
A13: Colin | B13: Cleaned the data, accessed and pulled the source data, and compiled it into a clean, submission-ready Excel file.
A14: Leah | B14: Identified a data category and dataset direction, organized team meetings, and asked clarifying questions to guide scope.
A15: Sean | B15: Evaluated and identified a dataset that fit the project rubric requirements.
A17: Q6 | B17: We chose this dataset because we all have an interest in sports analytics and enjoy watching basketball. We also are intrigued by the methods teams use to make contracts and evaluate performance. We hope to learn more about the ways player salaries are determined and analyze player and team performance through data, not just scores. We want to get more experience and gain understanding on the business of sports.
